Workbook
Name cfg_Currency: Settings!$D$5
Name cfg_DefaultContribution: Settings!$D$6
Name cfg_FinancialYear: Settings!$D$7
Name cfg_StartMonth: Settings!$D$8
Name cfg_MaxMembers: Settings!$D$9
Name cfg_Theme: Settings!$D$10

Sheet Dashboard
A1: BOARDING HOUSE UTILITY MANAGEMENT SYSTEM - FINANCIAL DASHBOARD
A2: Visual overview of collections, utility expenditures, active roommates, net savings, and cash flows
B4: CURRENT MONTH | D4: TOTAL MEMBERS | F4: PAID MEMBERS | H4: UNPAID MEMBERS | J4: EXPECTED COLLECTION | L4: COLLECTED AMOUNT | N4: COLLECTION RATE % | P4: Status | Q4: Count
B5: =TEXT(TODAY(), "MMMM YYYY") | D5: =COUNTIF(tbl_Members[Status], "Active")+COUNTIF(tbl_Members[Status], "Inactive") | F5: =COUNTIF(tbl_Collections[Status], "Paid")+COUNTIF(tbl_Collections[Status], "Late") | H5: =COUNTIF(tbl_Collections[Status], "Not Paid") | J5: =SUM(tbl_MonthlySummary[Expected Collection]) | L5: =SUM(tbl_MonthlySummary[Actual Collection]) | N5: =IF(J5=0, 0, L5/J5) | P5: Paid | Q5: =COUNTIF(tbl_Collections[Status], "Paid")
P6: Partial | Q6: =COUNTIF(tbl_Collections[Status], "Partial")
B7: OUTSTANDING AMOUNT | D7: WATER EXPENSES | F7: ELECTRICITY EXPENSES | H7: TOTAL EXPENSES | J7: CARRY FORWARD BALANCE | L7: NET SAVINGS BALANCE | P7: Not Paid | Q7: =COUNTIF(tbl_Collections[Status], "Not Paid")
B8: =SUM(tbl_Collections[Outstanding Balance]) | D8: =SUM(tbl_MonthlySummary[Water Bills]) | F8: =SUM(tbl_MonthlySummary[Electricity Bills]) | H8: =SUM(tbl_MonthlySummary[Total Expenses]) | J8: =Monthly_Summary!$J$16 | L8: =L5-H8 | P8: Late | Q8: =COUNTIF(tbl_Collections[Status], "Late")
B10: FINANCIAL TRENDS & ANALYTICS OVERVIEW

Sheet Members
A1: BOARDING HOUSE MEMBERS DIRECTORY
A2: Manage active roommate profiles, room allocations, phone numbers and contract terms
A4: Member ID | B4: Full Name | C4: Room Number | D4: Phone Number | E4: Status | F4: Join Date | G4: Leave Date | H4: Notes
A5: ="MBR" & TEXT(ROW() - 4, "000")
A6: ="MBR" & TEXT(ROW() - 4, "000")
A7: ="MBR" & TEXT(ROW() - 4, "000")
A8: ="MBR" & TEXT(ROW() - 4, "000")
A9: ="MBR" & TEXT(ROW() - 4, "000")
A10: ="MBR" & TEXT(ROW() - 4, "000")
A11: ="MBR" & TEXT(ROW() - 4, "000")
A12: ="MBR" & TEXT(ROW() - 4, "000")
A13: ="MBR" & TEXT(ROW() - 4, "000")
A14: ="MBR" & TEXT(ROW() - 4, "000")
A15: ="MBR" & TEXT(ROW() - 4, "000")

Sheet Monthly_Collections
A1: MONTHLY ROOM RENT & UTILITY COLLECTIONS
A2: Record payments, split utilities, track collections and manage roommate balance accounts
B4: TOTAL RENT COLLECTED | E4: TOTAL OUTSTANDING DUE | H4: COLLECTION RATE
B5: =SUM(tbl_Collections[Total Paid]) | E5: =SUM(tbl_Collections[Outstanding Balance]) | H5: =IF((SUM(tbl_Collections[Standard Contribution])+SUM(tbl_Collections[Extra Contribution]))=0,0,SUM(tbl_Collections[Total Paid])/(SUM(tbl_Collections[Standard Contribution])+SUM(tbl_Collections[Extra Contribution])))
A8: Month | B8: Member | C8: Standard Contribution | D8: Extra Contribution | E8: Advance Payment | F8: Partial Payment | G8: Total Paid | H8: Outstanding Balance | I8: Payment Date | J8: Payment Status | K8: Remarks
C9: =Settings!$D$6 | D9: 0 | E9: 0 | F9: 0 | G9: =[@[Partial Payment]]+[@[Advance Payment]]+[@[Extra Contribution]] | H9: =MAX(0, [@[Standard Contribution]]+[@[Extra Contribution]]-[@[Total Paid]]) | J9: =IF([@[Total Paid]]=0, "Not Paid", IF([@[Total Paid]]<([@[Standard Contribution]]+[@[Extra Contribution]]), "Partial", IF(AND([@[Payment Date]]<>"", DAY([@[Payment Date]])>10), "Late", "Paid")))
C10: =Settings!$D$6 | D10: 0 | E10: 0 | F10: 0 | G10: =[@[Partial Payment]]+[@[Advance Payment]]+[@[Extra Contribution]] | H10: =MAX(0, [@[Standard Contribution]]+[@[Extra Contribution]]-[@[Total Paid]]) | J10: =IF([@[Total Paid]]=0, "Not Paid", IF([@[Total Paid]]<([@[Standard Contribution]]+[@[Extra Contribution]]), "Partial", IF(AND([@[Payment Date]]<>"", DAY([@[Payment Date]])>10), "Late", "Paid")))
C11: =Settings!$D$6 | D11: 0 | E11: 0 | F11: 0 | G11: =[@[Partial Payment]]+[@[Advance Payment]]+[@[Extra Contribution]] | H11: =MAX(0, [@[Standard Contribution]]+[@[Extra Contribution]]-[@[Total Paid]]) | J11: =IF([@[Total Paid]]=0, "Not Paid", IF([@[Total Paid]]<([@[Standard Contribution]]+[@[Extra Contribution]]), "Partial", IF(AND([@[Payment Date]]<>"", DAY([@[Payment Date]])>10), "Late", "Paid")))
C12: =Settings!$D$6 | D12: 0 | E12: 0 | F12: 0 | G12: =[@[Partial Payment]]+[@[Advance Payment]]+[@[Extra Contribution]] | H12: =MAX(0, [@[Standard Contribution]]+[@[Extra Contribution]]-[@[Total Paid]]) | J12: =IF([@[Total Paid]]=0, "Not Paid", IF([@[Total Paid]]<([@[Standard Contribution]]+[@[Extra Contribution]]), "Partial", IF(AND([@[Payment Date]]<>"", DAY([@[Payment Date]])>10), "Late", "Paid")))
C13: =Settings!$D$6 | D13: 0 | E13: 0 | F13: 0 | G13: =[@[Partial Payment]]+[@[Advance Payment]]+[@[Extra Contribution]] | H13: =MAX(0, [@[Standard Contribution]]+[@[Extra Contribution]]-[@[Total Paid]]) | J13: =IF([@[Total Paid]]=0, "Not Paid", IF([@[Total Paid]]<([@[Standard Contribution]]+[@[Extra Contribution]]), "Partial", IF(AND([@[Payment Date]]<>"", DAY([@[Payment Date]])>10), "Late", "Paid")))
C14: =Settings!$D$6 | D14: 0 | E14: 0 | F14: 0 | G14: =[@[Partial Payment]]+[@[Advance Payment]]+[@[Extra Contribution]] | H14: =MAX(0, [@[Standard Contribution]]+[@[Extra Contribution]]-[@[Total Paid]]) | J14: =IF([@[Total Paid]]=0, "Not Paid", IF([@[Total Paid]]<([@[Standard Contribution]]+[@[Extra Contribution]]), "Partial", IF(AND([@[Payment Date]]<>"", DAY([@[Payment Date]])>10), "Late", "Paid")))
C15: =Settings!$D$6 | D15: 0 | E15: 0 | F15: 0 | G15: =[@[Partial Payment]]+[@[Advance Payment]]+[@[Extra Contribution]] | H15: =MAX(0, [@[Standard Contribution]]+[@[Extra Contribution]]-[@[Total Paid]]) | J15: =IF([@[Total Paid]]=0, "Not Paid", IF([@[Total Paid]]<([@[Standard Contribution]]+[@[Extra Contribution]]), "Partial", IF(AND([@[Payment Date]]<>"", DAY([@[Payment Date]])>10), "Late", "Paid")))
C16: =Settings!$D$6 | D16: 0 | E16: 0 | F16: 0 | G16: =[@[Partial Payment]]+[@[Advance Payment]]+[@[Extra Contribution]] | H16: =MAX(0, [@[Standard Contribution]]+[@[Extra Contribution]]-[@[Total Paid]]) | J16: =IF([@[Total Paid]]=0, "Not Paid", IF([@[Total Paid]]<([@[Standard Contribution]]+[@[Extra Contribution]]), "Partial", IF(AND([@[Payment Date]]<>"", DAY([@[Payment Date]])>10), "Late", "Paid")))
C17: =Settings!$D$6 | D17: 0 | E17: 0 | F17: 0 | G17: =[@[Partial Payment]]+[@[Advance Payment]]+[@[Extra Contribution]] | H17: =MAX(0, [@[Standard Contribution]]+[@[Extra Contribution]]-[@[Total Paid]]) | J17: =IF([@[Total Paid]]=0, "Not Paid", IF([@[Total Paid]]<([@[Standard Contribution]]+[@[Extra Contribution]]), "Partial", IF(AND([@[Payment Date]]<>"", DAY([@[Payment Date]])>10), "Late", "Paid")))
C18: =Settings!$D$6 | D18: 0 | E18: 0 | F18: 0 | G18: =[@[Partial Payment]]+[@[Advance Payment]]+[@[Extra Contribution]] | H18: =MAX(0, [@[Standard Contribution]]+[@[Extra Contribution]]-[@[Total Paid]]) | J18: =IF([@[Total Paid]]=0, "Not Paid", IF([@[Total Paid]]<([@[Standard Contribution]]+[@[Extra Contribution]]), "Partial", IF(AND([@[Payment Date]]<>"", DAY([@[Payment Date]])>10), "Late", "Paid")))
C19: =Settings!$D$6 | D19: 0 | E19: 0 | F19: 0 | G19: =[@[Partial Payment]]+[@[Advance Payment]]+[@[Extra Contribution]] | H19: =MAX(0, [@[Standard Contribution]]+[@[Extra Contribution]]-[@[Total Paid]]) | J19: =IF([@[Total Paid]]=0, "Not Paid", IF([@[Total Paid]]<([@[Standard Contribution]]+[@[Extra Contribution]]), "Partial", IF(AND([@[Payment Date]]<>"", DAY([@[Payment Date]])>10), "Late", "Paid")))

Sheet Utility_Bills
A1: UTILITY BILLS MASTER LOG
A2: Track Water, Electricity, Internet, Gas, Cleaning, and other boarding operational expenditures
A4: Month | B4: Water Bill | C4: Electricity Bill | D4: Internet | E4: Gas | F4: Cleaning | G4: Other Expenses | H4: Total Expenses | I4: Bill Paid Date | J4: Paid By | K4: Remarks
B5: 0 | C5: 0 | D5: 0 | E5: 0 | F5: 0 | G5: 0 | H5: =[@[Water Bill]]+[@[Electricity Bill]]+[@[Internet]]+[@[Gas]]+[@[Cleaning]]+[@[Other Expenses]]
B6: 0 | C6: 0 | D6: 0 | E6: 0 | F6: 0 | G6: 0 | H6: =[@[Water Bill]]+[@[Electricity Bill]]+[@[Internet]]+[@[Gas]]+[@[Cleaning]]+[@[Other Expenses]]
B7: 0 | C7: 0 | D7: 0 | E7: 0 | F7: 0 | G7: 0 | H7: =[@[Water Bill]]+[@[Electricity Bill]]+[@[Internet]]+[@[Gas]]+[@[Cleaning]]+[@[Other Expenses]]
B8: 0 | C8: 0 | D8: 0 | E8: 0 | F8: 0 | G8: 0 | H8: =[@[Water Bill]]+[@[Electricity Bill]]+[@[Internet]]+[@[Gas]]+[@[Cleaning]]+[@[Other Expenses]]
B9: 0 | C9: 0 | D9: 0 | E9: 0 | F9: 0 | G9: 0 | H9: =[@[Water Bill]]+[@[Electricity Bill]]+[@[Internet]]+[@[Gas]]+[@[Cleaning]]+[@[Other Expenses]]
B10: 0 | C10: 0 | D10: 0 | E10: 0 | F10: 0 | G10: 0 | H10: =[@[Water Bill]]+[@[Electricity Bill]]+[@[Internet]]+[@[Gas]]+[@[Cleaning]]+[@[Other Expenses]]
B11: 0 | C11: 0 | D11: 0 | E11: 0 | F11: 0 | G11: 0 | H11: =[@[Water Bill]]+[@[Electricity Bill]]+[@[Internet]]+[@[Gas]]+[@[Cleaning]]+[@[Other Expenses]]
B12: 0 | C12: 0 | D12: 0 | E12: 0 | F12: 0 | G12: 0 | H12: =[@[Water Bill]]+[@[Electricity Bill]]+[@[Internet]]+[@[Gas]]+[@[Cleaning]]+[@[Other Expenses]]
B13: 0 | C13: 0 | D13: 0 | E13: 0 | F13: 0 | G13: 0 | H13: =[@[Water Bill]]+[@[Electricity Bill]]+[@[Internet]]+[@[Gas]]+[@[Cleaning]]+[@[Other Expenses]]
B14: 0 | C14: 0 | D14: 0 | E14: 0 | F14: 0 | G14: 0 | H14: =[@[Water Bill]]+[@[Electricity Bill]]+[@[Internet]]+[@[Gas]]+[@[Cleaning]]+[@[Other Expenses]]
B15: 0 | C15: 0 | D15: 0 | E15: 0 | F15: 0 | G15: 0 | H15: =[@[Water Bill]]+[@[Electricity Bill]]+[@[Internet]]+[@[Gas]]+[@[Cleaning]]+[@[Other Expenses]]
B16: 0 | C16: 0 | D16: 0 | E16: 0 | F16: 0 | G16: 0 | H16: =[@[Water Bill]]+[@[Electricity Bill]]+[@[Internet]]+[@[Gas]]+[@[Cleaning]]+[@[Other Expenses]]

Sheet Monthly_Summary
A1: MONTHLY FINANCIAL PERFORMANCE SUMMARY
A2: Aggregated roommate collections, utility bills, other expenses, net cash flows, and carry-forward balances
A4: Month | B4: Expected Collection | C4: Actual Collection | D4: Water Bills | E4: Electricity Bills | F4: Other Expenses | G4: Total Expenses | H4: Surplus | I4: Deficit | J4: Carry Forward | K4: Remarks
B5: =COUNTIF(tbl_Members[Status], "Active") * Settings!$D$6 | C5: =SUMIFS(tbl_Collections[Total Paid], tbl_Collections[Month], [@[Month]]) | D5: =SUMIFS(tbl_UtilityBills[Water Bill], tbl_UtilityBills[Month], [@[Month]]) | E5: =SUMIFS(tbl_UtilityBills[Electricity Bill], tbl_UtilityBills[Month], [@[Month]]) | F5: =SUMIFS(tbl_UtilityBills[Internet], tbl_UtilityBills[Month], [@[Month]])+SUMIFS(tbl_UtilityBills[Gas], tbl_UtilityBills[Month], [@[Month]])+SUMIFS(tbl_UtilityBills[Cleaning], tbl_UtilityBills[Month], [@[Month]])+SUMIFS(tbl_UtilityBills[Other Expenses], tbl_UtilityBills[Month], [@[Month]]) | G5: =[@[Water Bills]]+[@[Electricity Bills]]+[@[Other Expenses]] | H5: =IF([@[Actual Collection]]>[@[Total Expenses]], [@[Actual Collection]]-[@[Total Expenses]], 0) | I5: =IF([@[Total Expenses]]>[@[Actual Collection]], [@[Total Expenses]]-[@[Actual Collection]], 0) | J5: =[@[Actual Collection]]-[@[Total Expenses]]
B6: =COUNTIF(tbl_Members[Status], "Active") * Settings!$D$6 | C6: =SUMIFS(tbl_Collections[Total Paid], tbl_Collections[Month], [@[Month]]) | D6: =SUMIFS(tbl_UtilityBills[Water Bill], tbl_UtilityBills[Month], [@[Month]]) | E6: =SUMIFS(tbl_UtilityBills[Electricity Bill], tbl_UtilityBills[Month], [@[Month]]) | F6: =SUMIFS(tbl_UtilityBills[Internet], tbl_UtilityBills[Month], [@[Month]])+SUMIFS(tbl_UtilityBills[Gas], tbl_UtilityBills[Month], [@[Month]])+SUMIFS(tbl_UtilityBills[Cleaning], tbl_UtilityBills[Month], [@[Month]])+SUMIFS(tbl_UtilityBills[Other Expenses], tbl_UtilityBills[Month], [@[Month]]) | G6: =[@[Water Bills]]+[@[Electricity Bills]]+[@[Other Expenses]] | H6: =IF([@[Actual Collection]]>[@[Total Expenses]], [@[Actual Collection]]-[@[Total Expenses]], 0) | I6: =IF([@[Total Expenses]]>[@[Actual Collection]], [@[Total Expenses]]-[@[Actual Collection]], 0) | J6: =J5+[@[Actual Collection]]-[@[Total Expenses]]
B7: =COUNTIF(tbl_Members[Status], "Active") * Settings!$D$6 | C7: =SUMIFS(tbl_Collections[Total Paid], tbl_Collections[Month], [@[Month]]) | D7: =SUMIFS(tbl_UtilityBills[Water Bill], tbl_UtilityBills[Month], [@[Month]]) | E7: =SUMIFS(tbl_UtilityBills[Electricity Bill], tbl_UtilityBills[Month], [@[Month]]) | F7: =SUMIFS(tbl_UtilityBills[Internet], tbl_UtilityBills[Month], [@[Month]])+SUMIFS(tbl_UtilityBills[Gas], tbl_UtilityBills[Month], [@[Month]])+SUMIFS(tbl_UtilityBills[Cleaning], tbl_UtilityBills[Month], [@[Month]])+SUMIFS(tbl_UtilityBills[Other Expenses], tbl_UtilityBills[Month], [@[Month]]) | G7: =[@[Water Bills]]+[@[Electricity Bills]]+[@[Other Expenses]] | H7: =IF([@[Actual Collection]]>[@[Total Expenses]], [@[Actual Collection]]-[@[Total Expenses]], 0) | I7: =IF([@[Total Expenses]]>[@[Actual Collection]], [@[Total Expenses]]-[@[Actual Collection]], 0) | J7: =J6+[@[Actual Collection]]-[@[Total Expenses]]
B8: =COUNTIF(tbl_Members[Status], "Active") * Settings!$D$6 | C8: =SUMIFS(tbl_Collections[Total Paid], tbl_Collections[Month], [@[Month]]) | D8: =SUMIFS(tbl_UtilityBills[Water Bill], tbl_UtilityBills[Month], [@[Month]]) | E8: =SUMIFS(tbl_UtilityBills[Electricity Bill], tbl_UtilityBills[Month], [@[Month]]) | F8: =SUMIFS(tbl_UtilityBills[Internet], tbl_UtilityBills[Month], [@[Month]])+SUMIFS(tbl_UtilityBills[Gas], tbl_UtilityBills[Month], [@[Month]])+SUMIFS(tbl_UtilityBills[Cleaning], tbl_UtilityBills[Month], [@[Month]])+SUMIFS(tbl_UtilityBills[Other Expenses], tbl_UtilityBills[Month], [@[Month]]) | G8: =[@[Water Bills]]+[@[Electricity Bills]]+[@[Other Expenses]] | H8: =IF([@[Actual Collection]]>[@[Total Expenses]], [@[Actual Collection]]-[@[Total Expenses]], 0) | I8: =IF([@[Total Expenses]]>[@[Actual Collection]], [@[Total Expenses]]-[@[Actual Collection]], 0) | J8: =J7+[@[Actual Collection]]-[@[Total Expenses]]
B9: =COUNTIF(tbl_Members[Status], "Active") * Settings!$D$6 | C9: =SUMIFS(tbl_Collections[Total Paid], tbl_Collections[Month], [@[Month]]) | D9: =SUMIFS(tbl_UtilityBills[Water Bill], tbl_UtilityBills[Month], [@[Month]]) | E9: =SUMIFS(tbl_UtilityBills[Electricity Bill], tbl_UtilityBills[Month], [@[Month]]) | F9: =SUMIFS(tbl_UtilityBills[Internet], tbl_UtilityBills[Month], [@[Month]])+SUMIFS(tbl_UtilityBills[Gas], tbl_UtilityBills[Month], [@[Month]])+SUMIFS(tbl_UtilityBills[Cleaning], tbl_UtilityBills[Month], [@[Month]])+SUMIFS(tbl_UtilityBills[Other Expenses], tbl_UtilityBills[Month], [@[Month]]) | G9: =[@[Water Bills]]+[@[Electricity Bills]]+[@[Other Expenses]] | H9: =IF([@[Actual Collection]]>[@[Total Expenses]], [@[Actual Collection]]-[@[Total Expenses]], 0) | I9: =IF([@[Total Expenses]]>[@[Actual Collection]], [@[Total Expenses]]-[@[Actual Collection]], 0) | J9: =J8+[@[Actual Collection]]-[@[Total Expenses]]
B10: =COUNTIF(tbl_Members[Status], "Active") * Settings!$D$6 | C10: =SUMIFS(tbl_Collections[Total Paid], tbl_Collections[Month], [@[Month]]) | D10: =SUMIFS(tbl_UtilityBills[Water Bill], tbl_UtilityBills[Month], [@[Month]]) | E10: =SUMIFS(tbl_UtilityBills[Electricity Bill], tbl_UtilityBills[Month], [@[Month]]) | F10: =SUMIFS(tbl_UtilityBills[Internet], tbl_UtilityBills[Month], [@[Month]])+SUMIFS(tbl_UtilityBills[Gas], tbl_UtilityBills[Month], [@[Month]])+SUMIFS(tbl_UtilityBills[Cleaning], tbl_UtilityBills[Month], [@[Month]])+SUMIFS(tbl_UtilityBills[Other Expenses], tbl_UtilityBills[Month], [@[Month]]) | G10: =[@[Water Bills]]+[@[Electricity Bills]]+[@[Other Expenses]] | H10: =IF([@[Actual Collection]]>[@[Total Expenses]], [@[Actual Collection]]-[@[Total Expenses]], 0) | I10: =IF([@[Total Expenses]]>[@[Actual Collection]], [@[Total Expenses]]-[@[Actual Collection]], 0) | J10: =J9+[@[Actual Collection]]-[@[Total Expenses]]
B11: =COUNTIF(tbl_Members[Status], "Active") * Settings!$D$6 | C11: =SUMIFS(tbl_Collections[Total Paid], tbl_Collections[Month], [@[Month]]) | D11: =SUMIFS(tbl_UtilityBills[Water Bill], tbl_UtilityBills[Month], [@[Month]]) | E11: =SUMIFS(tbl_UtilityBills[Electricity Bill], tbl_UtilityBills[Month], [@[Month]]) | F11: =SUMIFS(tbl_UtilityBills[Internet], tbl_UtilityBills[Month], [@[Month]])+SUMIFS(tbl_UtilityBills[Gas], tbl_UtilityBills[Month], [@[Month]])+SUMIFS(tbl_UtilityBills[Cleaning], tbl_UtilityBills[Month], [@[Month]])+SUMIFS(tbl_UtilityBills[Other Expenses], tbl_UtilityBills[Month], [@[Month]]) | G11: =[@[Water Bills]]+[@[Electricity Bills]]+[@[Other Expenses]] | H11: =IF([@[Actual Collection]]>[@[Total Expenses]], [@[Actual Collection]]-[@[Total Expenses]], 0) | I11: =IF([@[Total Expenses]]>[@[Actual Collection]], [@[Total Expenses]]-[@[Actual Collection]], 0) | J11: =J10+[@[Actual Collection]]-[@[Total Expenses]]
B12: =COUNTIF(tbl_Members[Status], "Active") * Settings!$D$6 | C12: =SUMIFS(tbl_Collections[Total Paid], tbl_Collections[Month], [@[Month]]) | D12: =SUMIFS(tbl_UtilityBills[Water Bill], tbl_UtilityBills[Month], [@[Month]]) | E12: =SUMIFS(tbl_UtilityBills[Electricity Bill], tbl_UtilityBills[Month], [@[Month]]) | F12: =SUMIFS(tbl_UtilityBills[Internet], tbl_UtilityBills[Month], [@[Month]])+SUMIFS(tbl_UtilityBills[Gas], tbl_UtilityBills[Month], [@[Month]])+SUMIFS(tbl_UtilityBills[Cleaning], tbl_UtilityBills[Month], [@[Month]])+SUMIFS(tbl_UtilityBills[Other Expenses], tbl_UtilityBills[Month], [@[Month]]) | G12: =[@[Water Bills]]+[@[Electricity Bills]]+[@[Other Expenses]] | H12: =IF([@[Actual Collection]]>[@[Total Expenses]], [@[Actual Collection]]-[@[Total Expenses]], 0) | I12: =IF([@[Total Expenses]]>[@[Actual Collection]], [@[Total Expenses]]-[@[Actual Collection]], 0) | J12: =J11+[@[Actual Collection]]-[@[Total Expenses]]
B13: =COUNTIF(tbl_Members[Status], "Active") * Settings!$D$6 | C13: =SUMIFS(tbl_Collections[Total Paid], tbl_Collections[Month], [@[Month]]) | D13: =SUMIFS(tbl_UtilityBills[Water Bill], tbl_UtilityBills[Month], [@[Month]]) | E13: =SUMIFS(tbl_UtilityBills[Electricity Bill], tbl_UtilityBills[Month], [@[Month]]) | F13: =SUMIFS(tbl_UtilityBills[Internet], tbl_UtilityBills[Month], [@[Month]])+SUMIFS(tbl_UtilityBills[Gas], tbl_UtilityBills[Month], [@[Month]])+SUMIFS(tbl_UtilityBills[Cleaning], tbl_UtilityBills[Month], [@[Month]])+SUMIFS(tbl_UtilityBills[Other Expenses], tbl_UtilityBills[Month], [@[Month]]) | G13: =[@[Water Bills]]+[@[Electricity Bills]]+[@[Other Expenses]] | H13: =IF([@[Actual Collection]]>[@[Total Expenses]], [@[Actual Collection]]-[@[Total Expenses]], 0) | I13: =IF([@[Total Expenses]]>[@[Actual Collection]], [@[Total Expenses]]-[@[Actual Collection]], 0) | J13: =J12+[@[Actual Collection]]-[@[Total Expenses]]
B14: =COUNTIF(tbl_Members[Status], "Active") * Settings!$D$6 | C14: =SUMIFS(tbl_Collections[Total Paid], tbl_Collections[Month], [@[Month]]) | D14: =SUMIFS(tbl_UtilityBills[Water Bill], tbl_UtilityBills[Month], [@[Month]]) | E14: =SUMIFS(tbl_UtilityBills[Electricity Bill], tbl_UtilityBills[Month], [@[Month]]) | F14: =SUMIFS(tbl_UtilityBills[Internet], tbl_UtilityBills[Month], [@[Month]])+SUMIFS(tbl_UtilityBills[Gas], tbl_UtilityBills[Month], [@[Month]])+SUMIFS(tbl_UtilityBills[Cleaning], tbl_UtilityBills[Month], [@[Month]])+SUMIFS(tbl_UtilityBills[Other Expenses], tbl_UtilityBills[Month], [@[Month]]) | G14: =[@[Water Bills]]+[@[Electricity Bills]]+[@[Other Expenses]] | H14: =IF([@[Actual Collection]]>[@[Total Expenses]], [@[Actual Collection]]-[@[Total Expenses]], 0) | I14: =IF([@[Total Expenses]]>[@[Actual Collection]], [@[Total Expenses]]-[@[Actual Collection]], 0) | J14: =J13+[@[Actual Collection]]-[@[Total Expenses]]
B15: =COUNTIF(tbl_Members[Status], "Active") * Settings!$D$6 | C15: =SUMIFS(tbl_Collections[Total Paid], tbl_Collections[Month], [@[Month]]) | D15: =SUMIFS(tbl_UtilityBills[Water Bill], tbl_UtilityBills[Month], [@[Month]]) | E15: =SUMIFS(tbl_UtilityBills[Electricity Bill], tbl_UtilityBills[Month], [@[Month]]) | F15: =SUMIFS(tbl_UtilityBills[Internet], tbl_UtilityBills[Month], [@[Month]])+SUMIFS(tbl_UtilityBills[Gas], tbl_UtilityBills[Month], [@[Month]])+SUMIFS(tbl_UtilityBills[Cleaning], tbl_UtilityBills[Month], [@[Month]])+SUMIFS(tbl_UtilityBills[Other Expenses], tbl_UtilityBills[Month], [@[Month]]) | G15: =[@[Water Bills]]+[@[Electricity Bills]]+[@[Other Expenses]] | H15: =IF([@[Actual Collection]]>[@[Total Expenses]], [@[Actual Collection]]-[@[Total Expenses]], 0) | I15: =IF([@[Total Expenses]]>[@[Actual Collection]], [@[Total Expenses]]-[@[Actual Collection]], 0) | J15: =J14+[@[Actual Collection]]-[@[Total Expenses]]
B16: =COUNTIF(tbl_Members[Status], "Active") * Settings!$D$6 | C16: =SUMIFS(tbl_Collections[Total Paid], tbl_Collections[Month], [@[Month]]) | D16: =SUMIFS(tbl_UtilityBills[Water Bill], tbl_UtilityBills[Month], [@[Month]]) | E16: =SUMIFS(tbl_UtilityBills[Electricity Bill], tbl_UtilityBills[Month], [@[Month]]) | F16: =SUMIFS(tbl_UtilityBills[Internet], tbl_UtilityBills[Month], [@[Month]])+SUMIFS(tbl_UtilityBills[Gas], tbl_UtilityBills[Month], [@[Month]])+SUMIFS(tbl_UtilityBills[Cleaning], tbl_UtilityBills[Month], [@[Month]])+SUMIFS(tbl_UtilityBills[Other Expenses], tbl_UtilityBills[Month], [@[Month]]) | G16: =[@[Water Bills]]+[@[Electricity Bills]]+[@[Other Expenses]] | H16: =IF([@[Actual Collection]]>[@[Total Expenses]], [@[Actual Collection]]-[@[Total Expenses]], 0) | I16: =IF([@[Total Expenses]]>[@[Actual Collection]], [@[Total Expenses]]-[@[Actual Collection]], 0) | J16: =J15+[@[Actual Collection]]-[@[Total Expenses]]

Sheet Payment_Tracker
A1: YEARLY ROOMMATE PAYMENT STATUS TRACKER
A2: Cross-tab visual matrix displaying roommate payment status (Paid, Partial, Not Paid, Late) by month
A4: Member Name | B4: April | C4: May | D4: June | E4: July | F4: August | G4: September | H4: October | I4: November | J4: December | K4: January | L4: February | M4: March
A5: =IFERROR(INDEX(tbl_Members[Full Name], ROW() - 4), "") | B5: =IF([@[Member Name]]="", "", IFERROR(INDEX(tbl_Collections[Status], MATCH(1, INDEX((tbl_Collections[Member]=[@[Member Name]]) * (tbl_Collections[Month]=B$4), 0), 0)), "Not Paid")) | C5: =IF([@[Member Name]]="", "", IFERROR(INDEX(tbl_Collections[Status], MATCH(1, INDEX((tbl_Collections[Member]=[@[Member Name]]) * (tbl_Collections[Month]=C$4), 0), 0)), "Not Paid")) | D5: =IF([@[Member Name]]="", "", IFERROR(INDEX(tbl_Collections[Status], MATCH(1, INDEX((tbl_Collections[Member]=[@[Member Name]]) * (tbl_Collections[Month]=D$4), 0), 0)), "Not Paid")) | E5: =IF([@[Member Name]]="", "", IFERROR(INDEX(tbl_Collections[Status], MATCH(1, INDEX((tbl_Collections[Member]=[@[Member Name]]) * (tbl_Collections[Month]=E$4), 0), 0)), "Not Paid")) | F5: =IF([@[Member Name]]="", "", IFERROR(INDEX(tbl_Collections[Status], MATCH(1, INDEX((tbl_Collections[Member]=[@[Member Name]]) * (tbl_Collections[Month]=F$4), 0), 0)), "Not Paid")) | G5: =IF([@[Member Name]]="", "", IFERROR(INDEX(tbl_Collections[Status], MATCH(1, INDEX((tbl_Collections[Member]=[@[Member Name]]) * (tbl_Collections[Month]=G$4), 0), 0)), "Not Paid")) | H5: =IF([@[Member Name]]="", "", IFERROR(INDEX(tbl_Collections[Status], MATCH(1, INDEX((tbl_Collections[Member]=[@[Member Name]]) * (tbl_Collections[Month]=H$4), 0), 0)), "Not Paid")) | I5: =IF([@[Member Name]]="", "", IFERROR(INDEX(tbl_Collections[Status], MATCH(1, INDEX((tbl_Collections[Member]=[@[Member Name]]) * (tbl_Collections[Month]=I$4), 0), 0)), "Not Paid")) | ... M5: =IF([@[Member Name]]="", "", IFERROR(INDEX(tbl_Collections[Status], MATCH(1, INDEX((tbl_Collections[Member]=[@[Member Name]]) * (tbl_Collections[Month]=M$4), 0), 0)), "Not Paid"))
A6: =IFERROR(INDEX(tbl_Members[Full Name], ROW() - 4), "") | B6: =IF([@[Member Name]]="", "", IFERROR(INDEX(tbl_Collections[Status], MATCH(1, INDEX((tbl_Collections[Member]=[@[Member Name]]) * (tbl_Collections[Month]=B$4), 0), 0)), "Not Paid")) | C6: =IF([@[Member Name]]="", "", IFERROR(INDEX(tbl_Collections[Status], MATCH(1, INDEX((tbl_Collections[Member]=[@[Member Name]]) * (tbl_Collections[Month]=C$4), 0), 0)), "Not Paid")) | D6: =IF([@[Member Name]]="", "", IFERROR(INDEX(tbl_Collections[Status], MATCH(1, INDEX((tbl_Collections[Member]=[@[Member Name]]) * (tbl_Collections[Month]=D$4), 0), 0)), "Not Paid")) | E6: =IF([@[Member Name]]="", "", IFERROR(INDEX(tbl_Collections[Status], MATCH(1, INDEX((tbl_Collections[Member]=[@[Member Name]]) * (tbl_Collections[Month]=E$4), 0), 0)), "Not Paid")) | F6: =IF([@[Member Name]]="", "", IFERROR(INDEX(tbl_Collections[Status], MATCH(1, INDEX((tbl_Collections[Member]=[@[Member Name]]) * (tbl_Collections[Month]=F$4), 0), 0)), "Not Paid")) | G6: =IF([@[Member Name]]="", "", IFERROR(INDEX(tbl_Collections[Status], MATCH(1, INDEX((tbl_Collections[Member]=[@[Member Name]]) * (tbl_Collections[Month]=G$4), 0), 0)), "Not Paid")) | H6: =IF([@[Member Name]]="", "", IFERROR(INDEX(tbl_Collections[Status], MATCH(1, INDEX((tbl_Collections[Member]=[@[Member Name]]) * (tbl_Collections[Month]=H$4), 0), 0)), "Not Paid")) | I6: =IF([@[Member Name]]="", "", IFERROR(INDEX(tbl_Collections[Status], MATCH(1, INDEX((tbl_Collections[Member]=[@[Member Name]]) * (tbl_Collections[Month]=I$4), 0), 0)), "Not Paid")) | ... M6: =IF([@[Member Name]]="", "", IFERROR(INDEX(tbl_Collections[Status], MATCH(1, INDEX((tbl_Collections[Member]=[@[Member Name]]) * (tbl_Collections[Month]=M$4), 0), 0)), "Not Paid"))
A7: =IFERROR(INDEX(tbl_Members[Full Name], ROW() - 4), "") | B7: =IF([@[Member Name]]="", "", IFERROR(INDEX(tbl_Collections[Status], MATCH(1, INDEX((tbl_Collections[Member]=[@[Member Name]]) * (tbl_Collections[Month]=B$4), 0), 0)), "Not Paid")) | C7: =IF([@[Member Name]]="", "", IFERROR(INDEX(tbl_Collections[Status], MATCH(1, INDEX((tbl_Collections[Member]=[@[Member Name]]) * (tbl_Collections[Month]=C$4), 0), 0)), "Not Paid")) | D7: =IF([@[Member Name]]="", "", IFERROR(INDEX(tbl_Collections[Status], MATCH(1, INDEX((tbl_Collections[Member]=[@[Member Name]]) * (tbl_Collections[Month]=D$4), 0), 0)), "Not Paid")) | E7: =IF([@[Member Name]]="", "", IFERROR(INDEX(tbl_Collections[Status], MATCH(1, INDEX((tbl_Collections[Member]=[@[Member Name]]) * (tbl_Collections[Month]=E$4), 0), 0)), "Not Paid")) | F7: =IF([@[Member Name]]="", "", IFERROR(INDEX(tbl_Collections[Status], MATCH(1, INDEX((tbl_Collections[Member]=[@[Member Name]]) * (tbl_Collections[Month]=F$4), 0), 0)), "Not Paid")) | G7: =IF([@[Member Name]]="", "", IFERROR(INDEX(tbl_Collections[Status], MATCH(1, INDEX((tbl_Collections[Member]=[@[Member Name]]) * (tbl_Collections[Month]=G$4), 0), 0)), "Not Paid")) | H7: =IF([@[Member Name]]="", "", IFERROR(INDEX(tbl_Collections[Status], MATCH(1, INDEX((tbl_Collections[Member]=[@[Member Name]]) * (tbl_Collections[Month]=H$4), 0), 0)), "Not Paid")) | I7: =IF([@[Member Name]]="", "", IFERROR(INDEX(tbl_Collections[Status], MATCH(1, INDEX((tbl_Collections[Member]=[@[Member Name]]) * (tbl_Collections[Month]=I$4), 0), 0)), "Not Paid")) | ... M7: =IF([@[Member Name]]="", "", IFERROR(INDEX(tbl_Collections[Status], MATCH(1, INDEX((tbl_Collections[Member]=[@[Member Name]]) * (tbl_Collections[Month]=M$4), 0), 0)), "Not Paid"))
A8: =IFERROR(INDEX(tbl_Members[Full Name], ROW() - 4), "") | B8: =IF([@[Member Name]]="", "", IFERROR(INDEX(tbl_Collections[Status], MATCH(1, INDEX((tbl_Collections[Member]=[@[Member Name]]) * (tbl_Collections[Month]=B$4), 0), 0)), "Not Paid")) | C8: =IF([@[Member Name]]="", "", IFERROR(INDEX(tbl_Collections[Status], MATCH(1, INDEX((tbl_Collections[Member]=[@[Member Name]]) * (tbl_Collections[Month]=C$4), 0), 0)), "Not Paid")) | D8: =IF([@[Member Name]]="", "", IFERROR(INDEX(tbl_Collections[Status], MATCH(1, INDEX((tbl_Collections[Member]=[@[Member Name]]) * (tbl_Collections[Month]=D$4), 0), 0)), "Not Paid")) | E8: =IF([@[Member Name]]="", "", IFERROR(INDEX(tbl_Collections[Status], MATCH(1, INDEX((tbl_Collections[Member]=[@[Member Name]]) * (tbl_Collections[Month]=E$4), 0), 0)), "Not Paid")) | F8: =IF([@[Member Name]]="", "", IFERROR(INDEX(tbl_Collections[Status], MATCH(1, INDEX((tbl_Collections[Member]=[@[Member Name]]) * (tbl_Collections[Month]=F$4), 0), 0)), "Not Paid")) | G8: =IF([@[Member Name]]="", "", IFERROR(INDEX(tbl_Collections[Status], MATCH(1, INDEX((tbl_Collections[Member]=[@[Member Name]]) * (tbl_Collections[Month]=G$4), 0), 0)), "Not Paid")) | H8: =IF([@[Member Name]]="", "", IFERROR(INDEX(tbl_Collections[Status], MATCH(1, INDEX((tbl_Collections[Member]=[@[Member Name]]) * (tbl_Collections[Month]=H$4), 0), 0)), "Not Paid")) | I8: =IF([@[Member Name]]="", "", IFERROR(INDEX(tbl_Collections[Status], MATCH(1, INDEX((tbl_Collections[Member]=[@[Member Name]]) * (tbl_Collections[Month]=I$4), 0), 0)), "Not Paid")) | ... M8: =IF([@[Member Name]]="", "", IFERROR(INDEX(tbl_Collections[Status], MATCH(1, INDEX((tbl_Collections[Member]=[@[Member Name]]) * (tbl_Collections[Month]=M$4), 0), 0)), "Not Paid"))
A9: =IFERROR(INDEX(tbl_Members[Full Name], ROW() - 4), "") | B9: =IF([@[Member Name]]="", "", IFERROR(INDEX(tbl_Collections[Status], MATCH(1, INDEX((tbl_Collections[Member]=[@[Member Name]]) * (tbl_Collections[Month]=B$4), 0), 0)), "Not Paid")) | C9: =IF([@[Member Name]]="", "", IFERROR(INDEX(tbl_Collections[Status], MATCH(1, INDEX((tbl_Collections[Member]=[@[Member Name]]) * (tbl_Collections[Month]=C$4), 0), 0)), "Not Paid")) | D9: =IF([@[Member Name]]="", "", IFERROR(INDEX(tbl_Collections[Status], MATCH(1, INDEX((tbl_Collections[Member]=[@[Member Name]]) * (tbl_Collections[Month]=D$4), 0), 0)), "Not Paid")) | E9: =IF([@[Member Name]]="", "", IFERROR(INDEX(tbl_Collections[Status], MATCH(1, INDEX((tbl_Collections[Member]=[@[Member Name]]) * (tbl_Collections[Month]=E$4), 0), 0)), "Not Paid")) | F9: =IF([@[Member Name]]="", "", IFERROR(INDEX(tbl_Collections[Status], MATCH(1, INDEX((tbl_Collections[Member]=[@[Member Name]]) * (tbl_Collections[Month]=F$4), 0), 0)), "Not Paid")) | G9: =IF([@[Member Name]]="", "", IFERROR(INDEX(tbl_Collections[Status], MATCH(1, INDEX((tbl_Collections[Member]=[@[Member Name]]) * (tbl_Collections[Month]=G$4), 0), 0)), "Not Paid")) | H9: =IF([@[Member Name]]="", "", IFERROR(INDEX(tbl_Collections[Status], MATCH(1, INDEX((tbl_Collections[Member]=[@[Member Name]]) * (tbl_Collections[Month]=H$4), 0), 0)), "Not Paid")) | I9: =IF([@[Member Name]]="", "", IFERROR(INDEX(tbl_Collections[Status], MATCH(1, INDEX((tbl_Collections[Member]=[@[Member Name]]) * (tbl_Collections[Month]=I$4), 0), 0)), "Not Paid")) | ... M9: =IF([@[Member Name]]="", "", IFERROR(INDEX(tbl_Collections[Status], MATCH(1, INDEX((tbl_Collections[Member]=[@[Member Name]]) * (tbl_Collections[Month]=M$4), 0), 0)), "Not Paid"))
A10: =IFERROR(INDEX(tbl_Members[Full Name], ROW() - 4), "") | B10: =IF([@[Member Name]]="", "", IFERROR(INDEX(tbl_Collections[Status], MATCH(1, INDEX((tbl_Collections[Member]=[@[Member Name]]) * (tbl_Collections[Month]=B$4), 0), 0)), "Not Paid")) | C10: =IF([@[Member Name]]="", "", IFERROR(INDEX(tbl_Collections[Status], MATCH(1, INDEX((tbl_Collections[Member]=[@[Member Name]]) * (tbl_Collections[Month]=C$4), 0), 0)), "Not Paid")) | D10: =IF([@[Member Name]]="", "", IFERROR(INDEX(tbl_Collections[Status], MATCH(1, INDEX((tbl_Collections[Member]=[@[Member Name]]) * (tbl_Collections[Month]=D$4), 0), 0)), "Not Paid")) | E10: =IF([@[Member Name]]="", "", IFERROR(INDEX(tbl_Collections[Status], MATCH(1, INDEX((tbl_Collections[Member]=[@[Member Name]]) * (tbl_Collections[Month]=E$4), 0), 0)), "Not Paid")) | F10: =IF([@[Member Name]]="", "", IFERROR(INDEX(tbl_Collections[Status], MATCH(1, INDEX((tbl_Collections[Member]=[@[Member Name]]) * (tbl_Collections[Month]=F$4), 0), 0)), "Not Paid")) | G10: =IF([@[Member Name]]="", "", IFERROR(INDEX(tbl_Collections[Status], MATCH(1, INDEX((tbl_Collections[Member]=[@[Member Name]]) * (tbl_Collections[Month]=G$4), 0), 0)), "Not Paid")) | H10: =IF([@[Member Name]]="", "", IFERROR(INDEX(tbl_Collections[Status], MATCH(1, INDEX((tbl_Collections[Member]=[@[Member Name]]) * (tbl_Collections[Month]=H$4), 0), 0)), "Not Paid")) | I10: =IF([@[Member Name]]="", "", IFERROR(INDEX(tbl_Collections[Status], MATCH(1, INDEX((tbl_Collections[Member]=[@[Member Name]]) * (tbl_Collections[Month]=I$4), 0), 0)), "Not Paid")) | ... M10: =IF([@[Member Name]]="", "", IFERROR(INDEX(tbl_Collections[Status], MATCH(1, INDEX((tbl_Collections[Member]=[@[Member Name]]) * (tbl_Collections[Month]=M$4), 0), 0)), "Not Paid"))
A11: =IFERROR(INDEX(tbl_Members[Full Name], ROW() - 4), "") | B11: =IF([@[Member Name]]="", "", IFERROR(INDEX(tbl_Collections[Status], MATCH(1, INDEX((tbl_Collections[Member]=[@[Member Name]]) * (tbl_Collections[Month]=B$4), 0), 0)), "Not Paid")) | C11: =IF([@[Member Name]]="", "", IFERROR(INDEX(tbl_Collections[Status], MATCH(1, INDEX((tbl_Collections[Member]=[@[Member Name]]) * (tbl_Collections[Month]=C$4), 0), 0)), "Not Paid")) | D11: =IF([@[Member Name]]="", "", IFERROR(INDEX(tbl_Collections[Status], MATCH(1, INDEX((tbl_Collections[Member]=[@[Member Name]]) * (tbl_Collections[Month]=D$4), 0), 0)), "Not Paid")) | E11: =IF([@[Member Name]]="", "", IFERROR(INDEX(tbl_Collections[Status], MATCH(1, INDEX((tbl_Collections[Member]=[@[Member Name]]) * (tbl_Collections[Month]=E$4), 0), 0)), "Not Paid")) | F11: =IF([@[Member Name]]="", "", IFERROR(INDEX(tbl_Collections[Status], MATCH(1, INDEX((tbl_Collections[Member]=[@[Member Name]]) * (tbl_Collections[Month]=F$4), 0), 0)), "Not Paid")) | G11: =IF([@[Member Name]]="", "", IFERROR(INDEX(tbl_Collections[Status], MATCH(1, INDEX((tbl_Collections[Member]=[@[Member Name]]) * (tbl_Collections[Month]=G$4), 0), 0)), "Not Paid")) | H11: =IF([@[Member Name]]="", "", IFERROR(INDEX(tbl_Collections[Status], MATCH(1, INDEX((tbl_Collections[Member]=[@[Member Name]]) * (tbl_Collections[Month]=H$4), 0), 0)), "Not Paid")) | I11: =IF([@[Member Name]]="", "", IFERROR(INDEX(tbl_Collections[Status], MATCH(1, INDEX((tbl_Collections[Member]=[@[Member Name]]) * (tbl_Collections[Month]=I$4), 0), 0)), "Not Paid")) | ... M11: =IF([@[Member Name]]="", "", IFERROR(INDEX(tbl_Collections[Status], MATCH(1, INDEX((tbl_Collections[Member]=[@[Member Name]]) * (tbl_Collections[Month]=M$4), 0), 0)), "Not Paid"))
A12: =IFERROR(INDEX(tbl_Members[Full Name], ROW() - 4), "") | B12: =IF([@[Member Name]]="", "", IFERROR(INDEX(tbl_Collections[Status], MATCH(1, INDEX((tbl_Collections[Member]=[@[Member Name]]) * (tbl_Collections[Month]=B$4), 0), 0)), "Not Paid")) | C12: =IF([@[Member Name]]="", "", IFERROR(INDEX(tbl_Collections[Status], MATCH(1, INDEX((tbl_Collections[Member]=[@[Member Name]]) * (tbl_Collections[Month]=C$4), 0), 0)), "Not Paid")) | D12: =IF([@[Member Name]]="", "", IFERROR(INDEX(tbl_Collections[Status], MATCH(1, INDEX((tbl_Collections[Member]=[@[Member Name]]) * (tbl_Collections[Month]=D$4), 0), 0)), "Not Paid")) | E12: =IF([@[Member Name]]="", "", IFERROR(INDEX(tbl_Collections[Status], MATCH(1, INDEX((tbl_Collections[Member]=[@[Member Name]]) * (tbl_Collections[Month]=E$4), 0), 0)), "Not Paid")) | F12: =IF([@[Member Name]]="", "", IFERROR(INDEX(tbl_Collections[Status], MATCH(1, INDEX((tbl_Collections[Member]=[@[Member Name]]) * (tbl_Collections[Month]=F$4), 0), 0)), "Not Paid")) | G12: =IF([@[Member Name]]="", "", IFERROR(INDEX(tbl_Collections[Status], MATCH(1, INDEX((tbl_Collections[Member]=[@[Member Name]]) * (tbl_Collections[Month]=G$4), 0), 0)), "Not Paid")) | H12: =IF([@[Member Name]]="", "", IFERROR(INDEX(tbl_Collections[Status], MATCH(1, INDEX((tbl_Collections[Member]=[@[Member Name]]) * (tbl_Collections[Month]=H$4), 0), 0)), "Not Paid")) | I12: =IF([@[Member Name]]="", "", IFERROR(INDEX(tbl_Collections[Status], MATCH(1, INDEX((tbl_Collections[Member]=[@[Member Name]]) * (tbl_Collections[Month]=I$4), 0), 0)), "Not Paid")) | ... M12: =IF([@[Member Name]]="", "", IFERROR(INDEX(tbl_Collections[Status], MATCH(1, INDEX((tbl_Collections[Member]=[@[Member Name]]) * (tbl_Collections[Month]=M$4), 0), 0)), "Not Paid"))
A13: =IFERROR(INDEX(tbl_Members[Full Name], ROW() - 4), "") | B13: =IF([@[Member Name]]="", "", IFERROR(INDEX(tbl_Collections[Status], MATCH(1, INDEX((tbl_Collections[Member]=[@[Member Name]]) * (tbl_Collections[Month]=B$4), 0), 0)), "Not Paid")) | C13: =IF([@[Member Name]]="", "", IFERROR(INDEX(tbl_Collections[Status], MATCH(1, INDEX((tbl_Collections[Member]=[@[Member Name]]) * (tbl_Collections[Month]=C$4), 0), 0)), "Not Paid")) | D13: =IF([@[Member Name]]="", "", IFERROR(INDEX(tbl_Collections[Status], MATCH(1, INDEX((tbl_Collections[Member]=[@[Member Name]]) * (tbl_Collections[Month]=D$4), 0), 0)), "Not Paid")) | E13: =IF([@[Member Name]]="", "", IFERROR(INDEX(tbl_Collections[Status], MATCH(1, INDEX((tbl_Collections[Member]=[@[Member Name]]) * (tbl_Collections[Month]=E$4), 0), 0)), "Not Paid")) | F13: =IF([@[Member Name]]="", "", IFERROR(INDEX(tbl_Collections[Status], MATCH(1, INDEX((tbl_Collections[Member]=[@[Member Name]]) * (tbl_Collections[Month]=F$4), 0), 0)), "Not Paid")) | G13: =IF([@[Member Name]]="", "", IFERROR(INDEX(tbl_Collections[Status], MATCH(1, INDEX((tbl_Collections[Member]=[@[Member Name]]) * (tbl_Collections[Month]=G$4), 0), 0)), "Not Paid")) | H13: =IF([@[Member Name]]="", "", IFERROR(INDEX(tbl_Collections[Status], MATCH(1, INDEX((tbl_Collections[Member]=[@[Member Name]]) * (tbl_Collections[Month]=H$4), 0), 0)), "Not Paid")) | I13: =IF([@[Member Name]]="", "", IFERROR(INDEX(tbl_Collections[Status], MATCH(1, INDEX((tbl_Collections[Member]=[@[Member Name]]) * (tbl_Collections[Month]=I$4), 0), 0)), "Not Paid")) | ... M13: =IF([@[Member Name]]="", "", IFERROR(INDEX(tbl_Collections[Status], MATCH(1, INDEX((tbl_Collections[Member]=[@[Member Name]]) * (tbl_Collections[Month]=M$4), 0), 0)), "Not Paid"))
A14: =IFERROR(INDEX(tbl_Members[Full Name], ROW() - 4), "") | B14: =IF([@[Member Name]]="", "", IFERROR(INDEX(tbl_Collections[Status], MATCH(1, INDEX((tbl_Collections[Member]=[@[Member Name]]) * (tbl_Collections[Month]=B$4), 0), 0)), "Not Paid")) | C14: =IF([@[Member Name]]="", "", IFERROR(INDEX(tbl_Collections[Status], MATCH(1, INDEX((tbl_Collections[Member]=[@[Member Name]]) * (tbl_Collections[Month]=C$4), 0), 0)), "Not Paid")) | D14: =IF([@[Member Name]]="", "", IFERROR(INDEX(tbl_Collections[Status], MATCH(1, INDEX((tbl_Collections[Member]=[@[Member Name]]) * (tbl_Collections[Month]=D$4), 0), 0)), "Not Paid")) | E14: =IF([@[Member Name]]="", "", IFERROR(INDEX(tbl_Collections[Status], MATCH(1, INDEX((tbl_Collections[Member]=[@[Member Name]]) * (tbl_Collections[Month]=E$4), 0), 0)), "Not Paid")) | F14: =IF([@[Member Name]]="", "", IFERROR(INDEX(tbl_Collections[Status], MATCH(1, INDEX((tbl_Collections[Member]=[@[Member Name]]) * (tbl_Collections[Month]=F$4), 0), 0)), "Not Paid")) | G14: =IF([@[Member Name]]="", "", IFERROR(INDEX(tbl_Collections[Status], MATCH(1, INDEX((tbl_Collections[Member]=[@[Member Name]]) * (tbl_Collections[Month]=G$4), 0), 0)), "Not Paid")) | H14: =IF([@[Member Name]]="", "", IFERROR(INDEX(tbl_Collections[Status], MATCH(1, INDEX((tbl_Collections[Member]=[@[Member Name]]) * (tbl_Collections[Month]=H$4), 0), 0)), "Not Paid")) | I14: =IF([@[Member Name]]="", "", IFERROR(INDEX(tbl_Collections[Status], MATCH(1, INDEX((tbl_Collections[Member]=[@[Member Name]]) * (tbl_Collections[Month]=I$4), 0), 0)), "Not Paid")) | ... M14: =IF([@[Member Name]]="", "", IFERROR(INDEX(tbl_Collections[Status], MATCH(1, INDEX((tbl_Collections[Member]=[@[Member Name]]) * (tbl_Collections[Month]=M$4), 0), 0)), "Not Paid"))
A15: =IFERROR(INDEX(tbl_Members[Full Name], ROW() - 4), "") | B15: =IF([@[Member Name]]="", "", IFERROR(INDEX(tbl_Collections[Status], MATCH(1, INDEX((tbl_Collections[Member]=[@[Member Name]]) * (tbl_Collections[Month]=B$4), 0), 0)), "Not Paid")) | C15: =IF([@[Member Name]]="", "", IFERROR(INDEX(tbl_Collections[Status], MATCH(1, INDEX((tbl_Collections[Member]=[@[Member Name]]) * (tbl_Collections[Month]=C$4), 0), 0)), "Not Paid")) | D15: =IF([@[Member Name]]="", "", IFERROR(INDEX(tbl_Collections[Status], MATCH(1, INDEX((tbl_Collections[Member]=[@[Member Name]]) * (tbl_Collections[Month]=D$4), 0), 0)), "Not Paid")) | E15: =IF([@[Member Name]]="", "", IFERROR(INDEX(tbl_Collections[Status], MATCH(1, INDEX((tbl_Collections[Member]=[@[Member Name]]) * (tbl_Collections[Month]=E$4), 0), 0)), "Not Paid")) | F15: =IF([@[Member Name]]="", "", IFERROR(INDEX(tbl_Collections[Status], MATCH(1, INDEX((tbl_Collections[Member]=[@[Member Name]]) * (tbl_Collections[Month]=F$4), 0), 0)), "Not Paid")) | G15: =IF([@[Member Name]]="", "", IFERROR(INDEX(tbl_Collections[Status], MATCH(1, INDEX((tbl_Collections[Member]=[@[Member Name]]) * (tbl_Collections[Month]=G$4), 0), 0)), "Not Paid")) | H15: =IF([@[Member Name]]="", "", IFERROR(INDEX(tbl_Collections[Status], MATCH(1, INDEX((tbl_Collections[Member]=[@[Member Name]]) * (tbl_Collections[Month]=H$4), 0), 0)), "Not Paid")) | I15: =IF([@[Member Name]]="", "", IFERROR(INDEX(tbl_Collections[Status], MATCH(1, INDEX((tbl_Collections[Member]=[@[Member Name]]) * (tbl_Collections[Month]=I$4), 0), 0)), "Not Paid")) | ... M15: =IF([@[Member Name]]="", "", IFERROR(INDEX(tbl_Collections[Status], MATCH(1, INDEX((tbl_Collections[Member]=[@[Member Name]]) * (tbl_Collections[Month]=M$4), 0), 0)), "Not Paid"))
A16: =IFERROR(INDEX(tbl_Members[Full Name], ROW() - 4), "") | B16: =IF([@[Member Name]]="", "", IFERROR(INDEX(tbl_Collections[Status], MATCH(1, INDEX((tbl_Collections[Member]=[@[Member Name]]) * (tbl_Collections[Month]=B$4), 0), 0)), "Not Paid")) | C16: =IF([@[Member Name]]="", "", IFERROR(INDEX(tbl_Collections[Status], MATCH(1, INDEX((tbl_Collections[Member]=[@[Member Name]]) * (tbl_Collections[Month]=C$4), 0), 0)), "Not Paid")) | D16: =IF([@[Member Name]]="", "", IFERROR(INDEX(tbl_Collections[Status], MATCH(1, INDEX((tbl_Collections[Member]=[@[Member Name]]) * (tbl_Collections[Month]=D$4), 0), 0)), "Not Paid")) | E16: =IF([@[Member Name]]="", "", IFERROR(INDEX(tbl_Collections[Status], MATCH(1, INDEX((tbl_Collections[Member]=[@[Member Name]]) * (tbl_Collections[Month]=E$4), 0), 0)), "Not Paid")) | F16: =IF([@[Member Name]]="", "", IFERROR(INDEX(tbl_Collections[Status], MATCH(1, INDEX((tbl_Collections[Member]=[@[Member Name]]) * (tbl_Collections[Month]=F$4), 0), 0)), "Not Paid")) | G16: =IF([@[Member Name]]="", "", IFERROR(INDEX(tbl_Collections[Status], MATCH(1, INDEX((tbl_Collections[Member]=[@[Member Name]]) * (tbl_Collections[Month]=G$4), 0), 0)), "Not Paid")) | H16: =IF([@[Member Name]]="", "", IFERROR(INDEX(tbl_Collections[Status], MATCH(1, INDEX((tbl_Collections[Member]=[@[Member Name]]) * (tbl_Collections[Month]=H$4), 0), 0)), "Not Paid")) | I16: =IF([@[Member Name]]="", "", IFERROR(INDEX(tbl_Collections[Status], MATCH(1, INDEX((tbl_Collections[Member]=[@[Member Name]]) * (tbl_Collections[Month]=I$4), 0), 0)), "Not Paid")) | ... M16: =IF([@[Member Name]]="", "", IFERROR(INDEX(tbl_Collections[Status], MATCH(1, INDEX((tbl_Collections[Member]=[@[Member Name]]) * (tbl_Collections[Month]=M$4), 0), 0)), "Not Paid"))

Sheet Expense_History
A1: BOARDING HOUSE TRANSACTIONAL EXPENSE MASTER LOG
A2: Record miscellaneous boarding expenditures (left) and monitor aggregated monthly collections vs expenses (right)
A4: Expense ID | B4: Date | C4: Month | D4: Category | E4: Description | F4: Amount (LKR) | G4: Paid To | H4: Payment Method | I4: Reference No | K4: Year-Month | L4: Total Collections | M4: Total Expenses | N4: Difference | O4: Carry Forward
A5: ="EXP" & TEXT(ROW() - 4, "000") | C5: =IF([@Date]="", "", TEXT([@Date], "MMMM YYYY")) | F5: 0 | K5: April 2026 | L5: =SUMIFS(tbl_Collections[Total Paid], tbl_Collections[Month], [@[Year-Month]]) | M5: =SUMIFS(tbl_UtilityBills[Total Expenses], tbl_UtilityBills[Month], [@[Year-Month]])+SUMIFS(tbl_ExpenseHistory[Amount (LKR)], tbl_ExpenseHistory[Month], [@[Year-Month]]) | N5: =[@[Total Collections]]-[@[Total Expenses]] | O5: =[@[Difference]]
A6: ="EXP" & TEXT(ROW() - 4, "000") | C6: =IF([@Date]="", "", TEXT([@Date], "MMMM YYYY")) | F6: 0 | K6: May 2026 | L6: =SUMIFS(tbl_Collections[Total Paid], tbl_Collections[Month], [@[Year-Month]]) | M6: =SUMIFS(tbl_UtilityBills[Total Expenses], tbl_UtilityBills[Month], [@[Year-Month]])+SUMIFS(tbl_ExpenseHistory[Amount (LKR)], tbl_ExpenseHistory[Month], [@[Year-Month]]) | N6: =[@[Total Collections]]-[@[Total Expenses]] | O6: =O5+[@[Difference]]
A7: ="EXP" & TEXT(ROW() - 4, "000") | C7: =IF([@Date]="", "", TEXT([@Date], "MMMM YYYY")) | F7: 0 | K7: June 2026 | L7: =SUMIFS(tbl_Collections[Total Paid], tbl_Collections[Month], [@[Year-Month]]) | M7: =SUMIFS(tbl_UtilityBills[Total Expenses], tbl_UtilityBills[Month], [@[Year-Month]])+SUMIFS(tbl_ExpenseHistory[Amount (LKR)], tbl_ExpenseHistory[Month], [@[Year-Month]]) | N7: =[@[Total Collections]]-[@[Total Expenses]] | O7: =O6+[@[Difference]]
A8: ="EXP" & TEXT(ROW() - 4, "000") | C8: =IF([@Date]="", "", TEXT([@Date], "MMMM YYYY")) | F8: 0 | K8: July 2026 | L8: =SUMIFS(tbl_Collections[Total Paid], tbl_Collections[Month], [@[Year-Month]]) | M8: =SUMIFS(tbl_UtilityBills[Total Expenses], tbl_UtilityBills[Month], [@[Year-Month]])+SUMIFS(tbl_ExpenseHistory[Amount (LKR)], tbl_ExpenseHistory[Month], [@[Year-Month]]) | N8: =[@[Total Collections]]-[@[Total Expenses]] | O8: =O7+[@[Difference]]
A9: ="EXP" & TEXT(ROW() - 4, "000") | C9: =IF([@Date]="", "", TEXT([@Date], "MMMM YYYY")) | F9: 0 | K9: August 2026 | L9: =SUMIFS(tbl_Collections[Total Paid], tbl_Collections[Month], [@[Year-Month]]) | M9: =SUMIFS(tbl_UtilityBills[Total Expenses], tbl_UtilityBills[Month], [@[Year-Month]])+SUMIFS(tbl_ExpenseHistory[Amount (LKR)], tbl_ExpenseHistory[Month], [@[Year-Month]]) | N9: =[@[Total Collections]]-[@[Total Expenses]] | O9: =O8+[@[Difference]]
A10: ="EXP" & TEXT(ROW() - 4, "000") | C10: =IF([@Date]="", "", TEXT([@Date], "MMMM YYYY")) | F10: 0 | K10: September 2026 | L10: =SUMIFS(tbl_Collections[Total Paid], tbl_Collections[Month], [@[Year-Month]]) | M10: =SUMIFS(tbl_UtilityBills[Total Expenses], tbl_UtilityBills[Month], [@[Year-Month]])+SUMIFS(tbl_ExpenseHistory[Amount (LKR)], tbl_ExpenseHistory[Month], [@[Year-Month]]) | N10: =[@[Total Collections]]-[@[Total Expenses]] | O10: =O9+[@[Difference]]
A11: ="EXP" & TEXT(ROW() - 4, "000") | C11: =IF([@Date]="", "", TEXT([@Date], "MMMM YYYY")) | F11: 0 | K11: October 2026 | L11: =SUMIFS(tbl_Collections[Total Paid], tbl_Collections[Month], [@[Year-Month]]) | M11: =SUMIFS(tbl_UtilityBills[Total Expenses], tbl_UtilityBills[Month], [@[Year-Month]])+SUMIFS(tbl_ExpenseHistory[Amount (LKR)], tbl_ExpenseHistory[Month], [@[Year-Month]]) | N11: =[@[Total Collections]]-[@[Total Expenses]] | O11: =O10+[@[Difference]]
A12: ="EXP" & TEXT(ROW() - 4, "000") | C12: =IF([@Date]="", "", TEXT([@Date], "MMMM YYYY")) | F12: 0 | K12: November 2026 | L12: =SUMIFS(tbl_Collections[Total Paid], tbl_Collections[Month], [@[Year-Month]]) | M12: =SUMIFS(tbl_UtilityBills[Total Expenses], tbl_UtilityBills[Month], [@[Year-Month]])+SUMIFS(tbl_ExpenseHistory[Amount (LKR)], tbl_ExpenseHistory[Month], [@[Year-Month]]) | N12: =[@[Total Collections]]-[@[Total Expenses]] | O12: =O11+[@[Difference]]
A13: ="EXP" & TEXT(ROW() - 4, "000") | C13: =IF([@Date]="", "", TEXT([@Date], "MMMM YYYY")) | F13: 0 | K13: December 2026 | L13: =SUMIFS(tbl_Collections[Total Paid], tbl_Collections[Month], [@[Year-Month]]) | M13: =SUMIFS(tbl_UtilityBills[Total Expenses], tbl_UtilityBills[Month], [@[Year-Month]])+SUMIFS(tbl_ExpenseHistory[Amount (LKR)], tbl_ExpenseHistory[Month], [@[Year-Month]]) | N13: =[@[Total Collections]]-[@[Total Expenses]] | O13: =O12+[@[Difference]]
A14: ="EXP" & TEXT(ROW() - 4, "000") | C14: =IF([@Date]="", "", TEXT([@Date], "MMMM YYYY")) | F14: 0 | K14: January 2027 | L14: =SUMIFS(tbl_Collections[Total Paid], tbl_Collections[Month], [@[Year-Month]]) | M14: =SUMIFS(tbl_UtilityBills[Total Expenses], tbl_UtilityBills[Month], [@[Year-Month]])+SUMIFS(tbl_ExpenseHistory[Amount (LKR)], tbl_ExpenseHistory[Month], [@[Year-Month]]) | N14: =[@[Total Collections]]-[@[Total Expenses]] | O14: =O13+[@[Difference]]
A15: ="EXP" & TEXT(ROW() - 4, "000") | C15: =IF([@Date]="", "", TEXT([@Date], "MMMM YYYY")) | F15: 0 | K15: February 2027 | L15: =SUMIFS(tbl_Collections[Total Paid], tbl_Collections[Month], [@[Year-Month]]) | M15: =SUMIFS(tbl_UtilityBills[Total Expenses], tbl_UtilityBills[Month], [@[Year-Month]])+SUMIFS(tbl_ExpenseHistory[Amount (LKR)], tbl_ExpenseHistory[Month], [@[Year-Month]]) | N15: =[@[Total Collections]]-[@[Total Expenses]] | O15: =O14+[@[Difference]]
K16: March 2027 | L16: =SUMIFS(tbl_Collections[Total Paid], tbl_Collections[Month], [@[Year-Month]]) | M16: =SUMIFS(tbl_UtilityBills[Total Expenses], tbl_UtilityBills[Month], [@[Year-Month]])+SUMIFS(tbl_ExpenseHistory[Amount (LKR)], tbl_ExpenseHistory[Month], [@[Year-Month]]) | N16: =[@[Total Collections]]-[@[Total Expenses]] | O16: =O15+[@[Difference]]

Sheet Analytics
A1: BOARDING HOUSE SYSTEM METRICS & TREND ANALYTICS
A2: Overview of cost variance, collections distribution, highest utility expenditures and roommate payment ledgers
B4: HIGHEST UTILITY BILL | D4: LOWEST UTILITY BILL | F4: AVERAGE MONTHLY BILL | H4: AVERAGE COLLECTION | J4: TOTAL OUTSTANDING DUE | L4: MAX MONTHLY DEFICIT
B5: =MAX(tbl_UtilityBills[Total Expenses]) | D5: =IF(SUM(tbl_UtilityBills[Total Expenses])=0, 0, MINIFS(tbl_UtilityBills[Total Expenses], tbl_UtilityBills[Total Expenses], ">0")) | F5: =IFERROR(AVERAGE(tbl_UtilityBills[Total Expenses]), 0) | H5: =IFERROR(AVERAGE(tbl_Collections[Total Paid]), 0) | J5: =SUM(tbl_Collections[Outstanding Balance]) | L5: =MAX(tbl_MonthlySummary[Deficit])
B8: Member Name | C8: Total Rent Paid | D8: Total Utilities Paid | E8: Outstanding Balances
B9: =IFERROR(INDEX(tbl_Members[Full Name], ROW() - ROW(tbl_MemberAnalytics[[#Headers],[Member Name]])), "") | C9: =IF([@[Member Name]]="", "", SUMIFS(tbl_Collections[Partial Payment], tbl_Collections[Member], [@[Member Name]])) | D9: =IF([@[Member Name]]="", "", SUMIFS(tbl_Collections[Extra Contribution], tbl_Collections[Member], [@[Member Name]])) | E9: =IF([@[Member Name]]="", "", SUMIFS(tbl_Collections[Outstanding Balance], tbl_Collections[Member], [@[Member Name]]))
B10: =IFERROR(INDEX(tbl_Members[Full Name], ROW() - ROW(tbl_MemberAnalytics[[#Headers],[Member Name]])), "") | C10: =IF([@[Member Name]]="", "", SUMIFS(tbl_Collections[Partial Payment], tbl_Collections[Member], [@[Member Name]])) | D10: =IF([@[Member Name]]="", "", SUMIFS(tbl_Collections[Extra Contribution], tbl_Collections[Member], [@[Member Name]])) | E10: =IF([@[Member Name]]="", "", SUMIFS(tbl_Collections[Outstanding Balance], tbl_Collections[Member], [@[Member Name]]))
B11: =IFERROR(INDEX(tbl_Members[Full Name], ROW() - ROW(tbl_MemberAnalytics[[#Headers],[Member Name]])), "") | C11: =IF([@[Member Name]]="", "", SUMIFS(tbl_Collections[Partial Payment], tbl_Collections[Member], [@[Member Name]])) | D11: =IF([@[Member Name]]="", "", SUMIFS(tbl_Collections[Extra Contribution], tbl_Collections[Member], [@[Member Name]])) | E11: =IF([@[Member Name]]="", "", SUMIFS(tbl_Collections[Outstanding Balance], tbl_Collections[Member], [@[Member Name]]))
B12: =IFERROR(INDEX(tbl_Members[Full Name], ROW() - ROW(tbl_MemberAnalytics[[#Headers],[Member Name]])), "") | C12: =IF([@[Member Name]]="", "", SUMIFS(tbl_Collections[Partial Payment], tbl_Collections[Member], [@[Member Name]])) | D12: =IF([@[Member Name]]="", "", SUMIFS(tbl_Collections[Extra Contribution], tbl_Collections[Member], [@[Member Name]])) | E12: =IF([@[Member Name]]="", "", SUMIFS(tbl_Collections[Outstanding Balance], tbl_Collections[Member], [@[Member Name]]))
B13: =IFERROR(INDEX(tbl_Members[Full Name], ROW() - ROW(tbl_MemberAnalytics[[#Headers],[Member Name]])), "") | C13: =IF([@[Member Name]]="", "", SUMIFS(tbl_Collections[Partial Payment], tbl_Collections[Member], [@[Member Name]])) | D13: =IF([@[Member Name]]="", "", SUMIFS(tbl_Collections[Extra Contribution], tbl_Collections[Member], [@[Member Name]])) | E13: =IF([@[Member Name]]="", "", SUMIFS(tbl_Collections[Outstanding Balance], tbl_Collections[Member], [@[Member Name]]))
B14: =IFERROR(INDEX(tbl_Members[Full Name], ROW() - ROW(tbl_MemberAnalytics[[#Headers],[Member Name]])), "") | C14: =IF([@[Member Name]]="", "", SUMIFS(tbl_Collections[Partial Payment], tbl_Collections[Member], [@[Member Name]])) | D14: =IF([@[Member Name]]="", "", SUMIFS(tbl_Collections[Extra Contribution], tbl_Collections[Member], [@[Member Name]])) | E14: =IF([@[Member Name]]="", "", SUMIFS(tbl_Collections[Outstanding Balance], tbl_Collections[Member], [@[Member Name]]))
B15: =IFERROR(INDEX(tbl_Members[Full Name], ROW() - ROW(tbl_MemberAnalytics[[#Headers],[Member Name]])), "") | C15: =IF([@[Member Name]]="", "", SUMIFS(tbl_Collections[Partial Payment], tbl_Collections[Member], [@[Member Name]])) | D15: =IF([@[Member Name]]="", "", SUMIFS(tbl_Collections[Extra Contribution], tbl_Collections[Member], [@[Member Name]])) | E15: =IF([@[Member Name]]="", "", SUMIFS(tbl_Collections[Outstanding Balance], tbl_Collections[Member], [@[Member Name]]))
B16: =IFERROR(INDEX(tbl_Members[Full Name], ROW() - ROW(tbl_MemberAnalytics[[#Headers],[Member Name]])), "") | C16: =IF([@[Member Name]]="", "", SUMIFS(tbl_Collections[Partial Payment], tbl_Collections[Member], [@[Member Name]])) | D16: =IF([@[Member Name]]="", "", SUMIFS(tbl_Collections[Extra Contribution], tbl_Collections[Member], [@[Member Name]])) | E16: =IF([@[Member Name]]="", "", SUMIFS(tbl_Collections[Outstanding Balance], tbl_Collections[Member], [@[Member Name]]))
B17: =IFERROR(INDEX(tbl_Members[Full Name], ROW() - ROW(tbl_MemberAnalytics[[#Headers],[Member Name]])), "") | C17: =IF([@[Member Name]]="", "", SUMIFS(tbl_Collections[Partial Payment], tbl_Collections[Member], [@[Member Name]])) | D17: =IF([@[Member Name]]="", "", SUMIFS(tbl_Collections[Extra Contribution], tbl_Collections[Member], [@[Member Name]])) | E17: =IF([@[Member Name]]="", "", SUMIFS(tbl_Collections[Outstanding Balance], tbl_Collections[Member], [@[Member Name]]))
B18: =IFERROR(INDEX(tbl_Members[Full Name], ROW() - ROW(tbl_MemberAnalytics[[#Headers],[Member Name]])), "") | C18: =IF([@[Member Name]]="", "", SUMIFS(tbl_Collections[Partial Payment], tbl_Collections[Member], [@[Member Name]])) | D18: =IF([@[Member Name]]="", "", SUMIFS(tbl_Collections[Extra Contribution], tbl_Collections[Member], [@[Member Name]])) | E18: =IF([@[Member Name]]="", "", SUMIFS(tbl_Collections[Outstanding Balance], tbl_Collections[Member], [@[Member Name]]))
B19: =IFERROR(INDEX(tbl_Members[Full Name], ROW() - ROW(tbl_MemberAnalytics[[#Headers],[Member Name]])), "") | C19: =IF([@[Member Name]]="", "", SUMIFS(tbl_Collections[Partial Payment], tbl_Collections[Member], [@[Member Name]])) | D19: =IF([@[Member Name]]="", "", SUMIFS(tbl_Collections[Extra Contribution], tbl_Collections[Member], [@[Member Name]])) | E19: =IF([@[Member Name]]="", "", SUMIFS(tbl_Collections[Outstanding Balance], tbl_Collections[Member], [@[Member Name]]))

Sheet Reports
B1: BOARDING HOUSE UTILITY MANAGEMENT SYSTEM - REPORTS BINDER
B3: 1. MONTHLY COLLECTION SUMMARY REPORT
B4: Month | C4: Member Name | D4: Rent Due | E4: Utilities Due | F4: Total Paid | G4: Outstanding
B5: =IFERROR(INDEX(tbl_Collections[Month], ROW() - 4), "") | C5: =IFERROR(INDEX(tbl_Collections[Member], ROW() - 4), "") | D5: =IFERROR(INDEX(tbl_Collections[Standard Contribution], ROW() - 4), 0) | E5: =IFERROR(INDEX(tbl_Collections[Extra Contribution], ROW() - 4), 0) | F5: =IFERROR(INDEX(tbl_Collections[Total Paid], ROW() - 4), 0) | G5: =IFERROR(INDEX(tbl_Collections[Outstanding Balance], ROW() - 4), 0)
B6: =IFERROR(INDEX(tbl_Collections[Month], ROW() - 4), "") | C6: =IFERROR(INDEX(tbl_Collections[Member], ROW() - 4), "") | D6: =IFERROR(INDEX(tbl_Collections[Standard Contribution], ROW() - 4), 0) | E6: =IFERROR(INDEX(tbl_Collections[Extra Contribution], ROW() - 4), 0) | F6: =IFERROR(INDEX(tbl_Collections[Total Paid], ROW() - 4), 0) | G6: =IFERROR(INDEX(tbl_Collections[Outstanding Balance], ROW() - 4), 0)
B7: =IFERROR(INDEX(tbl_Collections[Month], ROW() - 4), "") | C7: =IFERROR(INDEX(tbl_Collections[Member], ROW() - 4), "") | D7: =IFERROR(INDEX(tbl_Collections[Standard Contribution], ROW() - 4), 0) | E7: =IFERROR(INDEX(tbl_Collections[Extra Contribution], ROW() - 4), 0) | F7: =IFERROR(INDEX(tbl_Collections[Total Paid], ROW() - 4), 0) | G7: =IFERROR(INDEX(tbl_Collections[Outstanding Balance], ROW() - 4), 0)
B8: =IFERROR(INDEX(tbl_Collections[Month], ROW() - 4), "") | C8: =IFERROR(INDEX(tbl_Collections[Member], ROW() - 4), "") | D8: =IFERROR(INDEX(tbl_Collections[Standard Contribution], ROW() - 4), 0) | E8: =IFERROR(INDEX(tbl_Collections[Extra Contribution], ROW() - 4), 0) | F8: =IFERROR(INDEX(tbl_Collections[Total Paid], ROW() - 4), 0) | G8: =IFERROR(INDEX(tbl_Collections[Outstanding Balance], ROW() - 4), 0)
B9: =IFERROR(INDEX(tbl_Collections[Month], ROW() - 4), "") | C9: =IFERROR(INDEX(tbl_Collections[Member], ROW() - 4), "") | D9: =IFERROR(INDEX(tbl_Collections[Standard Contribution], ROW() - 4), 0) | E9: =IFERROR(INDEX(tbl_Collections[Extra Contribution], ROW() - 4), 0) | F9: =IFERROR(INDEX(tbl_Collections[Total Paid], ROW() - 4), 0) | G9: =IFERROR(INDEX(tbl_Collections[Outstanding Balance], ROW() - 4), 0)
B10: =IFERROR(INDEX(tbl_Collections[Month], ROW() - 4), "") | C10: =IFERROR(INDEX(tbl_Collections[Member], ROW() - 4), "") | D10: =IFERROR(INDEX(tbl_Collections[Standard Contribution], ROW() - 4), 0) | E10: =IFERROR(INDEX(tbl_Collections[Extra Contribution], ROW() - 4), 0) | F10: =IFERROR(INDEX(tbl_Collections[Total Paid], ROW() - 4), 0) | G10: =IFERROR(INDEX(tbl_Collections[Outstanding Balance], ROW() - 4), 0)
B11: =IFERROR(INDEX(tbl_Collections[Month], ROW() - 4), "") | C11: =IFERROR(INDEX(tbl_Collections[Member], ROW() - 4), "") | D11: =IFERROR(INDEX(tbl_Collections[Standard Contribution], ROW() - 4), 0) | E11: =IFERROR(INDEX(tbl_Collections[Extra Contribution], ROW() - 4), 0) | F11: =IFERROR(INDEX(tbl_Collections[Total Paid], ROW() - 4), 0) | G11: =IFERROR(INDEX(tbl_Collections[Outstanding Balance], ROW() - 4), 0)
B12: =IFERROR(INDEX(tbl_Collections[Month], ROW() - 4), "") | C12: =IFERROR(INDEX(tbl_Collections[Member], ROW() - 4), "") | D12: =IFERROR(INDEX(tbl_Collections[Standard Contribution], ROW() - 4), 0) | E12: =IFERROR(INDEX(tbl_Collections[Extra Contribution], ROW() - 4), 0) | F12: =IFERROR(INDEX(tbl_Collections[Total Paid], ROW() - 4), 0) | G12: =IFERROR(INDEX(tbl_Collections[Outstanding Balance], ROW() - 4), 0)
B13: =IFERROR(INDEX(tbl_Collections[Month], ROW() - 4), "") | C13: =IFERROR(INDEX(tbl_Collections[Member], ROW() - 4), "") | D13: =IFERROR(INDEX(tbl_Collections[Standard Contribution], ROW() - 4), 0) | E13: =IFERROR(INDEX(tbl_Collections[Extra Contribution], ROW() - 4), 0) | F13: =IFERROR(INDEX(tbl_Collections[Total Paid], ROW() - 4), 0) | G13: =IFERROR(INDEX(tbl_Collections[Outstanding Balance], ROW() - 4), 0)
B14: =IFERROR(INDEX(tbl_Collections[Month], ROW() - 4), "") | C14: =IFERROR(INDEX(tbl_Collections[Member], ROW() - 4), "") | D14: =IFERROR(INDEX(tbl_Collections[Standard Contribution], ROW() - 4), 0) | E14: =IFERROR(INDEX(tbl_Collections[Extra Contribution], ROW() - 4), 0) | F14: =IFERROR(INDEX(tbl_Collections[Total Paid], ROW() - 4), 0) | G14: =IFERROR(INDEX(tbl_Collections[Outstanding Balance], ROW() - 4), 0)
B15: =IFERROR(INDEX(tbl_Collections[Month], ROW() - 4), "") | C15: =IFERROR(INDEX(tbl_Collections[Member], ROW() - 4), "") | D15: =IFERROR(INDEX(tbl_Collections[Standard Contribution], ROW() - 4), 0) | E15: =IFERROR(INDEX(tbl_Collections[Extra Contribution], ROW() - 4), 0) | F15: =IFERROR(INDEX(tbl_Collections[Total Paid], ROW() - 4), 0) | G15: =IFERROR(INDEX(tbl_Collections[Outstanding Balance], ROW() - 4), 0)
B16: =IFERROR(INDEX(tbl_Collections[Month], ROW() - 4), "") | C16: =IFERROR(INDEX(tbl_Collections[Member], ROW() - 4), "") | D16: =IFERROR(INDEX(tbl_Collections[Standard Contribution], ROW() - 4), 0) | E16: =IFERROR(INDEX(tbl_Collections[Extra Contribution], ROW() - 4), 0) | F16: =IFERROR(INDEX(tbl_Collections[Total Paid], ROW() - 4), 0) | G16: =IFERROR(INDEX(tbl_Collections[Outstanding Balance], ROW() - 4), 0)
B18: 2. MONTHLY EXPENSE BREAKDOWN REPORT
B19: Month | C19: Water Bill | D19: Electricity Bill | E19: Internet Share | F19: Cleaning & Gas | G19: Total Expenses
